Workbook

Sheet Dashboard
A1: Partnership Pipeline — Dashboard
A2: Live summary across all three rings. Data pulls from Ring 1, Ring 2, and Ring 3 sheets.
A4: PIPELINE BY RING | B4: Partners | C4: High Priority | D4: Contacted+ | G4: RING 2 — BY COUNTRY | H4: Entities | I4: Status
A5: 🟢 Ring 1 — LU Institutions | B5: =COUNTA('Ring 1 — LU Institutions'!A2:A100) -> 27 | C5: =COUNTIF('Ring 1 — LU Institutions'!C2:C100,"High") -> 12 | D5: =COUNTIFS('Ring 1 — LU Institutions'!D2:D100,"<>Researching",'Ring 1 — LU Institutions'!D2:D100,"<>",'Ring 1 — LU Institutions'!D2:D100,"<>Not Started") -> 0 | G5: PT — Portugal | H5: =COUNTIF('Ring 2 — Communities'!B:B,"PT") -> 1 | I5: =IFERROR(INDEX('Ring 2 — Communities'!E:E,MATCH("PT",'Ring 2 — Communities'!B:B,0)),"-") -> Researching
A6: 🟣 Ring 2 — Country Communities | B6: =COUNTA('Ring 2 — Communities'!A2:A99) -> 12 | C6: =COUNTIF('Ring 2 — Communities'!D2:D99,"High") -> 8 | D6: =COUNTIFS('Ring 2 — Communities'!E2:E99,"<>Researching",'Ring 2 — Communities'!E2:E99,"<>",'Ring 2 — Communities'!E2:E99,"<>Not Started") -> 0 | G6: FR — France | H6: =COUNTIF('Ring 2 — Communities'!B:B,"FR") -> 1 | I6: =IFERROR(INDEX('Ring 2 — Communities'!E:E,MATCH("FR",'Ring 2 — Communities'!B:B,0)),"-") -> Researching
A7: 🔴 Ring 3 — Abroad (Stage 2) | B7: =COUNTA('Ring 3 — Abroad (Stage 2)'!A2:A100) -> 0 | C7: =COUNTIF('Ring 3 — Abroad (Stage 2)'!D2:D100,"High") -> 0 | D7: =COUNTIFS('Ring 3 — Abroad (Stage 2)'!E2:E100,"<>Researching",'Ring 3 — Abroad (Stage 2)'!E2:E100,"<>",'Ring 3 — Abroad (Stage 2)'!E2:E100,"<>Not Started") -> 0 | G7: IT — Italy | H7: =COUNTIF('Ring 2 — Communities'!B:B,"IT") -> 1 | I7: =IFERROR(INDEX('Ring 2 — Communities'!E:E,MATCH("IT",'Ring 2 — Communities'!B:B,0)),"-") -> Researching
A8: Total | B8: =SUM(B5:B7) -> 39 | C8: =SUM(C5:C7) -> 20 | D8: =SUM(D5:D7) -> 0 | G8: BE — Belgium | H8: =COUNTIF('Ring 2 — Communities'!B:B,"BE") -> 1 | I8: =IFERROR(INDEX('Ring 2 — Communities'!E:E,MATCH("BE",'Ring 2 — Communities'!B:B,0)),"-") -> Researching
G9: DE — Germany | H9: =COUNTIF('Ring 2 — Communities'!B:B,"DE") -> 1 | I9: =IFERROR(INDEX('Ring 2 — Communities'!E:E,MATCH("DE",'Ring 2 — Communities'!B:B,0)),"—") -> Researching
A10: STATUS TRACKER | B10: Ring 1 | C10: Ring 2 | D10: Ring 3 | E10: Total | G10: ES — Spain | H10: =COUNTIF('Ring 2 — Communities'!B:B,"ES") -> 1 | I10: =IFERROR(INDEX('Ring 2 — Communities'!E:E,MATCH("ES",'Ring 2 — Communities'!B:B,0)),"-") -> Researching
A11: Researching | B11: =COUNTIF('Ring 1 — LU Institutions'!D:D,"Researching") -> 27 | C11: =COUNTIF('Ring 2 — Communities'!E:E,"Researching") -> 12 | D11: =COUNTIF('Ring 3 — Abroad (Stage 2)'!E:E,"Researching") -> 0 | E11: =SUM(B11:D11) -> 39 | G11: CH — Switzerland | H11: =COUNTIF('Ring 2 — Communities'!B:B,"CH") -> 1 | I11: =IFERROR(INDEX('Ring 2 — Communities'!E:E,MATCH("CH",'Ring 2 — Communities'!B:B,0)),"-") -> Researching
A12: Contacted | B12: =COUNTIF('Ring 1 — LU Institutions'!D:D,"Contacted") -> 0 | C12: =COUNTIF('Ring 2 — Communities'!E:E,"Contacted") -> 0 | D12: =COUNTIF('Ring 3 — Abroad (Stage 2)'!E:E,"Contacted") -> 0 | E12: =SUM(B12:D12) -> 0 | G12: PL — Poland | H12: =COUNTIF('Ring 2 — Communities'!B:B,"PL") -> 1 | I12: =IFERROR(INDEX('Ring 2 — Communities'!E:E,MATCH("PL",'Ring 2 — Communities'!B:B,0)),"-") -> Researching
A13: In Discussion | B13: =COUNTIF('Ring 1 — LU Institutions'!D:D,"In Discussion") -> 0 | C13: =COUNTIF('Ring 2 — Communities'!E:E,"In Discussion") -> 0 | D13: =COUNTIF('Ring 3 — Abroad (Stage 2)'!E:E,"In Discussion") -> 0 | E13: =SUM(B13:D13) -> 0 | G13: UK / US — EN-speaking | H13: =COUNTIFS('Ring 2 — Communities'!B:B,"*EN-speaking*") -> 2 | I13: =IFERROR(INDEX('Ring 2 — Communities'!E:E,MATCH("US / EN-speaking",'Ring 2 — Communities'!B:B,0)),"—") -> Researching
A14: Active Partner | B14: =COUNTIF('Ring 1 — LU Institutions'!D:D,"Active Partner") -> 0 | C14: =COUNTIF('Ring 2 — Communities'!E:E,"Active Partner") -> 0 | D14: =COUNTIF('Ring 3 — Abroad (Stage 2)'!E:E,"Active Partner") -> 0 | E14: =SUM(B14:D14) -> 0 | G14: RO — Romania | H14: =COUNTIF('Ring 2 — Communities'!B:B,"RO") -> 1 | I14: =IFERROR(INDEX('Ring 2 — Communities'!E:E,MATCH("RO",'Ring 2 — Communities'!B:B,0)),"—") -> Researching
G15: IN — India | H15: =COUNTIF('Ring 2 — Communities'!B:B,"IN") -> 0 | I15: =IFERROR(INDEX('Ring 2 — Communities'!E:E,MATCH("IN",'Ring 2 — Communities'!B:B,0)),"—") -> —
G16: Nordic — DK/FI/IS/NO/SE | H16: =COUNTIF('Ring 2 — Communities'!B:B,"Nordic") -> 1 | I16: =IFERROR(INDEX('Ring 2 — Communities'!E:E,MATCH("Nordic",'Ring 2 — Communities'!B:B,0)),"—") -> Researching
A17: On Hold | B17: =COUNTIF('Ring 1 — LU Institutions'!D:D,"On Hold") -> 0 | C17: =COUNTIF('Ring 2 — Communities'!E:E,"On Hold") -> 0 | D17: =COUNTIF('Ring 3 — Abroad (Stage 2)'!E:E,"On Hold") -> 0 | E17: =SUM(B17:D17) -> 0 | G17: RING 1 — BY CATEGORY | H17: Count
A18: Not a Fit | B18: =COUNTIF('Ring 1 — LU Institutions'!D:D,"Not a Fit") -> 0 | C18: =COUNTIF('Ring 2 — Communities'!E:E,"Not a Fit") -> 0 | D18: =COUNTIF('Ring 3 — Abroad (Stage 2)'!E:E,"Not a Fit") -> 0 | E18: =SUM(B18:D18) -> 0 | G18: Hub / Public Body | H18: =COUNTIF('Ring 1 — LU Institutions'!B:B,"Hub / Public Body") -> 10
G19: Federation | H19: =COUNTIF('Ring 1 — LU Institutions'!B:B,"Federation") -> 14
G20: Chamber | H20: =COUNTIF('Ring 1 — LU Institutions'!B:B,"Chamber") -> 1
G21: Media | H21: =COUNTIF('Ring 1 — LU Institutions'!B:B,"Media") -> 1
G22: HR Network | H22: =COUNTIF('Ring 1 — LU Institutions'!B:B,"HR Network") -> 1

Sheet Draft
A1: Organization | B1: Why They Care | C1: Our Interest | D1: Main Message | E1: Partnership Type | F1: Access Conditions | G1: Support They Can Offer | H1: What We Offer | I1: Contact Person | J1: Need to Confirm | K1: Priority | L1: Status
A2: House of Entrepreneurship | B2: We offer useful value-add for people with international careers; fits their mission to inform, guide, and connect entrepreneurs | C2: Access to founders and internationally mobile entrepreneurs through workshops and advisor referrals; visibility in the entrepreneurship ecosystem; practical support and ecosystem introductions. | D2: We help employers and internationally mobile professionals with international careers understand and organize pension rights across countries | E2: Workshop / content / pilot / ecosystem intro | F2: Likely mission-based, free first contact; no public membership requirement found | G2: Advisor meeting, workshop opportunity, intros, feedback | H2: Workshop, guide, pilot session | I2: info@houseofentrepreneurship.lu | J2: Whether formal promotion or repeated collaboration needs separate arrangement | K2: High | L2: Researching
A3: Luxembourg Chamber of Commerce (cc.lu) | B3: Better support offer for member companies and internationally active businesses | C3: Reach employers, SMEs, and international business members via Chamber channels, events, and International Affairs | D3: We help employers and internationally mobile professionals with international careers understand and organize pension rights across countries | E3: Event / B2B intro / content / referral | F3: Core contact is open; deeper visibility may depend on Chamber process or membership context | G3: Intros, event route, international business access | H3: Employer-facing content, pilot, educational session | I3: Amrita Singh — Matchmaking Coordinator, International Affairs — amrita.singh@cc.lu | J3: Whether access to member-facing formats needs extra conditions | K3: High | L3: Researching
A4: House of Startups (HoST) | B4: We offer useful value-add for people with international careers; fits their mission to inform, guide, and connect entrepreneurs | C4: Access to startup founders and startup employees; visibility in the startup ecosystem; pilot-user access and community support. | D4: We help founders and startup talent with international careers get clarity on fragmented pension rights | E4: Workshop / content / pilot / ecosystem intro | F4: Likely open for first contact; deeper activation may depend on ecosystem fit or resident status | G4: Startup-community access, pilot audience, event/community route | H4: Workshop, guide, pilot session | I4: reception@host.lu | J4: Whether access to resident startups or event slots needs internal sponsor | K4: High | L4: Researching
A5: LHoFT | B5: Strong fintech / wealthtech / employee-financial-wellbeing angle; relevant to financial innovation and ecosystem collaboration | C5: Access to fintech, employers, and innovation partners; strong ecosystem visibility and credibility; support through introductions and pilot discussions. | D5: We are building a retirement-rights solution for internationally mobile professionals and employers | E5: Fintech partnership / pilot / ecosystem intro / employer-benefit discussion | F5: Likely selective and fit-driven | G5: Ecosystem credibility, intros, pilot conversations, event route | H5: Fintech use case, thought leadership, pilot, validation insights | J5: Whether membership/incubation is needed for deeper support | K5: High | L5: Researching
A6: Luxinnovation | B6: Relevant if they see us as an innovation/startup project with partner-finding and market-launch potential | C6: Reach startup ecosystem, innovation partners, and scaling-support structures through their startup and partner-finding support | D6: We are building a retirement-rights solution for internationally mobile professionals and employers | E6: Innovation support / partner finding / scaling support | F6: Mission-based support for innovation projects | G6: Partner finding, startup support, market-launch preparation, funding orientation | H6: Innovation case, ecosystem contribution, pilot | I6: Inna Perepelytsya — Senior Advisor — inna.perepelytsya@luxinnovation.lu Sven Baltes — Manager – Startup Relations — sven.baltes@luxinnovation.lu | J6: Whether they see the project as strong enough innovation fit | K6: Medium-High | L6: Researching
A7: AMCHAM Luxembourg | B7: We offer relevant member value for international companies and international employees; fits their information/problem-solving role | C7: Reach English-speaking employers, expat professionals, HR contacts, and member companies through events and committees | D7: We help international professionals and employers navigate fragmented pension rights built across Europe | E7: Event / employer pilot / content / committee discussion | F7: Likely member-driven; collaboration may depend on format or sponsorship | G7: Member events, employer visibility, committee access, newsletters | H7: Educational session, employer-benefit angle, guide, sharing news on changes in pension rights. | I7: Daniel McKenzie — Head of Communications, Events and Committee Structures — daniel@amcham.lu | J7: Whether speaking or content visibility needs membership or sponsor status or can start as external expert contribution | K7: High | L7: Researching
A8: British Chamber of Commerce | B8: We offer relevant member value for international companies and international employees; fits their event-based knowledge sharing | C8: Reach English-speaking employers, expat professionals, HR contacts, and member companies through events and committees | D8: We help international professionals and employers navigate fragmented pension rights built across Europe | E8: Event / content / community pilot / referrals | F8: Likely member-driven; collaboration may depend on format or sponsorship | G8: Community access,Events, business forums, member network | H8: Educational session, employer-benefit angle, guide, sharing news on changes in pension rights. | I8: Rebecca Kellagher — Manager — rebecca.kellagher@bcc.lu | J8: Whether speaking or content visibility needs membership or sponsor status or can start as external expert contribution | K8: High | L8: Researching
A9: CCIPL / Portugal–Luxembourg Chamber(ccill.lu) | B9: Highly relevant member/community topic for Portugal-linked entrepreneurs and professionals; fits their business support and matchmaking role | C9: Reach Portugal-linked founders, professionals, firms, and their event/newsletter audience | D9: We help Portugal–Luxembourg professionals understand and organize pension rights across countries | E9: Event / content / community pilot / referrals | F9: Likely member-driven; collaboration may depend on format or sponsorship | G9: Community access, events, business introductions, newsletter potential, visibility | H9: Portugal–Luxembourg pension session, guide, pilot | I9: info@ccill.lu | J9: Whether speaking or content visibility needs membership or sponsor status or can start as external expert contribution | K9: High | L9: Researching
A10: Luxembourg-Poland Chamber of Commerce (LPCC) (lpcc.lu) | B10: Relevant member/community topic for Poland-linked entrepreneurs and professionals; fits their business support and matchmaking role | C10: Reach Poland-linked founders, professionals, firms, and their event/newsletter audience | D10: We help internationally mobile professionals with Poland-linked careers organize pension rights across countries | E10: Event / content / community pilot / referrals | F10: Likely member-driven; collaboration may depend on format or sponsorship | G10: Community access, events, business introductions, newsletter potential, visibility | H10: Poland–Lux session, guide, pilot group | I10: Oliwia Gertych — Digital Marketer & Project Manager — oliwia.gertych@lpcc.lu | J10: Whether speaking or content visibility needs membership or sponsor status or can start as external expert contribution | K10: Medium-High | L10: Researching
A11: Official Spanish Chamber of Commerce in Belgium and Luxembourg (e-camara.com) | B11: Relevant member/community topic for Spain-linked entrepreneurs and professionals; fits their business support and matchmaking role | C11: Reach Spain-linked founders, professionals, firms, and their event/newsletter audience | D11: We help internationally mobile professionals with Spain-linked careers organize pension rights across countries | E11: Event / content / community pilot / referrals | F11: Likely member-driven; collaboration may depend on format or sponsorship (direct contact? ) | G11: Community access, events, business introductions, newsletter potential, visibility | H11: Spain–Lux session, guide, pilot group | I11: luxemburgo@e-camara.com | J11: Whether speaking or content visibility needs membership or sponsor status or can start as external expert contribution | K11: Medium-High | L11: Researching
A12: Luxembourg-Italian Chamber of Commerce | B12: Relevant topic for Italy-linked companies and professionals in Luxembourg, especially since Italy is one of our product expansion markets | C12: Reach Italy-linked founders, professionals, firms, and their event/newsletter audience | D12: We help Italy–Luxembourg professionals understand and organize pension rights across countries | E12: Event / content / community pilot / referrals | F12: Likely chamber-based; direct outreach possible | G12: Bilateral network, events, visibility, member access | H12: Italy–Lux pension education session, practical guide, pilot audience | I12: Luisa Castelli Secrétaire général / Directeur — l.castelli@ccil.lu | J12: Whether speaking or content visibility needs membership or sponsor status or can start as external expert contribution | K12: High | L12: Researching
A13: CCI France Luxembourg | B13: Highly relevant member/community topic for France-linked entrepreneurs and professionals; fits their business support and matchmaking role | C13: Reach France-linked founders, professionals, firms, and their event/newsletter audience; strong credibility in the France–Lux corridor | D13: We help internationally mobile professionals with France-linked careers organize pension rights across countries | E13: Event / content / community pilot / referrals | F13: Clear membership model and business club logic; first contact open, deeper visibility likely easier through partnership or member-style collaboration | G13: Community access, events, business introductions, newsletter potential, visibility | H13: France–Lux pension session, practical guide, employer-facing content, pilot | I13: Alexandra Benel, Director — alexandra.benel@cfci.lu; general cfci@cfci.lu | J13: Whether speaking or content visibility needs membership or sponsor status or can start as external expert contribution | K13: High | L13: Researching
A14: Business Club Luxemburg-Schweiz | B14: Highly relevant member/community topic for Switzerland-linked entrepreneurs and professionals; fits their business support and matchmaking role | C14: Reach Switzerland-linked founders, professionals, firms, and their event/newsletter audience | D14: We help Switzerland–Luxembourg professionals bring clarity to fragmented pension rights and occupational/private retirement assets across countries | E14: Event / content / community pilot / referrals | F14: Accredited bilateral business club, but detailed public access conditions need confirmation through direct contact via Chamber bilateral route | G14: Community access, events, business introductions, newsletter potential, visibility | H14: Swiss–Lux pension education session, practical cross-border guide, pilot audience | J14: Whether speaking or content visibility needs membership or sponsor status or can start as external expert contribution | K14: Low (they don’t have a big network) | L14: Researching
A15: Business Club Belgium-Luxembourg (BCBL) | B15: Highly relevant member/community topic for France-linked entrepreneurs and professionals; fits their business support and matchmaking role | C15: Reach Belgian-linked companies, professionals, firms, and their event/newsletter audience | D15: We help internationally mobile professionals with Belgium-linked careers organize pension rights across countries | E15: Event / content / community pilot / referrals | F15: Appears to be member-based business club; first contact open; deeper collaboration likely depends on club format or membership/sponsorship | G15: Community access, events, business introductions, newsletter potential, visibility | H15: Belgium–Lux pension session, practical guide, pilot group, employer-facing content | I15: contact@bcbl.be | J15: Whether speaking or content visibility needs membership or sponsor status or can start as external expert contribution | K15: High | L15: Researching
A16: Social Business Incubator (SBI) | B16: If positioned as financial inclusion / long-term resilience for internationally mobile people, it fits their social-impact support logic | C16: Reach social entrepreneurs, impact projects, and communities where financial clarity is part of social inclusion | D16: We want to improve long-term financial clarity and pension access for internationally mobile people | E16: Impact partnership / workshop / ecosystem intro | F16: Likely mission-based support | G16: Advice, training, impact-network intros, social positioning | H16: Financial wellbeing / inclusion workshop, impact framing | I16: contact@sbi.lu | J16: Whether our project is impact-oriented enough for active support | K16: Medium | L16: Researching
A17: Luxembourg Employers’ Association (UEL) | B17: Our solution can support employers dealing with internationally mobile employees and long-term employee wellbeing topics | C17: Reach employers, business leaders, and employer associations; strong B2B credibility and policy-level visibility | D17: We help employers support internationally mobile employees facing fragmented pension rights across countries | E17: Employer pilot / policy discussion / event / content | F17: Likely institutional and selective; contact possible through public route | G17: Employer credibility, possible introductions, policy/business visibility | H17: Employer-benefit angle, educational content, pilot idea | I17: Jean-Paul Olinger / public route press@uel.lu | J17: Best operational contact and whether topic fits their agenda | K17: High | L17: Researching
A18: ALFI – Association of the Luxembourg Fund Industry | B18: Relevant if positioned around international finance professionals, mobility, and long-term retirement/wealth-planning literacy | C18: Reach international finance professionals, member firms, and industry visibility in Luxembourg finance ecosystem | D18: We help employers support internationally mobile employees facing fragmented pension rights across countries | E18: Thought leadership / event / finance-community content | F18: Likely member-driven and industry-focused | G18: Events, premium visibility, finance-network access | H18: Educational session, finance-focused guide, premium pilot audience | J18: Whether they would see this as relevant beyond investment/fund topics | K18: Medium-High | L18: Researching
A19: Luxembourg for Finance (LFF) | B19: Strong fit for the international-finance and international-talent angle; your topic is relevant for globally mobile finance professionals | C19: Reach international finance audience, institutions, and financial-ecosystem visibility | D19: We help employers support internationally mobile employees facing fragmented pension rights across countries | E19: Event / ecosystem intro / thought leadership / visibility | F19: Likely institutional and fit-driven | G19: Visibility, finance-community access, ecosystem introductions | H19: Finance-professional guide, panel topic, educational session | I19: Jonathan WESTHEAD — Head of Communications — jonathan.westhead@lff.lu | J19: Whether they would host or circulate a topic like this | K19: Medium-High | L19: Researching
A20: FEDIL – The Voice of Luxembourg’s Industry | B20: Relevant for employers with international talent and cross-border workforce management needs | C20: Reach industrial employers, HR/business leaders, and employer network visibility | D20: We help employers support internationally mobile employees facing fragmented pension rights across countries | E20: Employer pilot / event / content / referrals | F20: Likely association-based and agenda-driven | G20: Employer network, business visibility, sector reach | H20: Employer-facing workshop, international-workforce support angle | J20: Best contact person and whether topic fits employer agenda | K20: Medium-High | L20: Researching
A21: APSI Luxembourg | B21: Relevant if positioned as digital infrastructure / fintech / regtech / employee-digital-services topic | C21: Reach Luxembourg tech community, digital leaders, and ecosystem visibility | D21: We help employers support internationally mobile employees facing fragmented pension rights across countries | E21: Ecosystem intro / event / visibility / tech-community content | F21: Likely association/community-based | G21: Tech visibility, digital ecosystem access, possible event channel | H21: Digital-use-case angle, startup/fintech story, product demo | J21: Whether they are a strong enough GTM route versus only visibility | K21: Medium | L21: Researching
A22: LPEA – Luxembourg Private Equity & Venture Capital Association | B22: Our solution is relevant to an international finance audience with highly mobile careers; LPEA’s mission is to connect, inform, and represent the PE/VC ecosystem. | C22: Reach PE/VC firms, private banks, family offices, advisors, and highly international professionals; gain premium finance visibility and potential employer-level access. | D22: We help internationally mobile professionals and employers in finance understand and organize fragmented pension rights across countries. | E22: Event / thought leadership / employer pilot / finance-community content | F22: Clear membership-based association, but direct contact is open. | G22: Events, network access, industry visibility, premium-segment credibility, knowledge-sharing platform. | H22: Finance-focused educational session, premium professional guide, pilot group, thought leadership content. | I22: Claus Mansfeldt — President— claus.mansfeldt@lpea.lu Stephane Pesch — CEO — stephane.pesch@lpea.lu Johann Herz — Head of Events & Communication — johann.herz@lpea.lu | J22: Whether non-members can speak, publish, or co-host; best operational contact beyond general office. | K22: Medium-High | L22: Researching
A23: LBAN – Luxembourg Business Angel Network | B23: Relevant if we position the solution for founders, investors, and internationally mobile startup operators; LBAN’s mission is to connect business angels with the entrepreneurial ecosystem and support startup growth. | C23: Reach angel investors, founders, startup teams, and ecosystem actors; gain startup/investor visibility and possible intros to founder communities and early adopters. | D23: We help internationally mobile professionals and employers in finance understand and organize fragmented pension rights across countries. | E23: Event / startup-investor content / ecosystem intro / pilot | F23: Membership/network-based, but general contact is open. | G23: Investor/startup ecosystem visibility, founder access, event/network route, community credibility. | H23: Founder/investor education session, startup-team guide, pilot-user angle, ecosystem content. | I23: info@lban.lu; public contacts include Michel Rzonzef (President)and Teona Khubutia (Manager). | J23: Whether they see the topic as relevant enough for members; whether event/content collaboration requires membership or sponsor route. | K23: Medium | L23: Researching
A24: ABBL?
A25: Maison Moderne / Paperjam / Delano | B25: Strong editorial relevance if framed as international talent, retirement fragmentation, and employer/expat financial clarity in Luxembourg | C25: Reach business audience, employers, decision-makers, and broad Luxembourg visibility through media exposure | D25: We are building a retirement-rights solution for internationally mobile professionals and employers | E25: Media / thought leadership / interview / article | F25: Editorial fit required; not a classic partnership | G25: Visibility, credibility, audience reach, story amplification | H25: Article angle, expert commentary, ecosystem story | I25: Aaron Grunwald — Editor-in-chief at Delano — aaron.grunwald@maisonmoderne.com Thierry Labro — Editor-in-chief at Delano — thierry.labro@maisonmoderne.com | J25: Best story angle: expat, talent, pensions, founder journey, or fintech | K25: High | L25: Researching

Sheet Ring 1 — LU Institutions
A1: Organization | B1: Category | C1: Priority | D1: Status | E1: Next Action | F1: GTM Role | G1: Why They Care | H1: Our Interest | I1: Main Message | J1: Partnership Type | K1: Access Conditions | L1: Support They Can Offer | M1: What We Offer | N1: Contact Person | O1: Need to Confirm
A2: House of Entrepreneurship | B2: Hub / Public Body | C2: High | D2: Researching | E2: Identify contact at House of Entrepreneurship; check upcoming startup events to attend | F2: Ecosystem intro, workshops, pilot users | G2: We offer useful value-add for people with international careers; fits their mission to inform, guide, and connect entrepreneurs | H2: Access to founders and internationally mobile entrepreneurs through workshops and advisor referrals; visibility in the entrepreneurship ecosystem; practical support and ecosystem introductions. | I2: We help employers and internationally mobile professionals with international careers understand and organize pension rights across countries | J2: Workshop / content / pilot / ecosystem intro | K2: Likely mission-based, free first contact; no public membership requirement found | L2: Advisor meeting, workshop opportunity, intros, feedback | M2: Workshop, guide, pilot session | N2: info@houseofentrepreneurship.lu | O2: Whether formal promotion or repeated collaboration needs separate arrangement
A3: Luxembourg Chamber of Commerce (cc.lu) | B3: Chamber | C3: High | D3: Researching | E3: Check CC events calendar; explore membership or partnership application route | F3: B2B intros, employer reach, events | G3: Better support offer for member companies and internationally active businesses | H3: Reach employers, SMEs, and international business members via Chamber channels, events, and International Affairs | I3: We help employers and internationally mobile professionals with international careers understand and organize pension rights across countries | J3: Event / B2B intro / content / referral | K3: Core contact is open; deeper visibility may depend on Chamber process or membership context | L3: Intros, event route, international business access | M3: Employer-facing content, pilot, educational session | N3: Amrita Singh — Matchmaking Coordinator, International Affairs — amrita.singh@cc.lu | O3: Whether access to member-facing formats needs extra conditions
A4: House of Startups (HoST) | B4: Hub / Public Body | C4: High | D4: Researching | E4: Contact HoST reception; ask about hosting a pension-rights workshop for startups | F4: Startup community, pilot users, events | G4: We offer useful value-add for people with international careers; fits their mission to inform, guide, and connect entrepreneurs | H4: Access to startup founders and startup employees; visibility in the startup ecosystem; pilot-user access and community support. | I4: We help founders and startup talent with international careers get clarity on fragmented pension rights | J4: Workshop / content / pilot / ecosystem intro | K4: Likely open for first contact; deeper activation may depend on ecosystem fit or resident status | L4: Startup-community access, pilot audience, event/community route | M4: Workshop, guide, pilot session | N4: reception@host.lu | O4: Whether access to resident startups or event slots needs internal sponsor
A5: LHoFT | B5: Hub / Public Body | C5: High | D5: Researching | E5: Contact LHoFT team; propose fintech-meets-pension session for resident startups | F5: Fintech credibility, pilot, ecosystem intros | G5: Strong fintech / wealthtech / employee-financial-wellbeing angle; relevant to financial innovation and ecosystem collaboration | H5: Access to fintech, employers, and innovation partners; strong ecosystem visibility and credibility; support through introductions and pilot discussions. | I5: We are building a retirement-rights solution for internationally mobile professionals and employers | J5: Fintech partnership / pilot / ecosystem intro / employer-benefit discussion | K5: Likely selective and fit-driven | L5: Ecosystem credibility, intros, pilot conversations, event route | M5: Fintech use case, thought leadership, pilot, validation insights | O5: Whether membership/incubation is needed for deeper support
A6: Luxinnovation | B6: Hub / Public Body | C6: Medium-High | D6: Researching | E6: Explore Fit 4 Start or partner program; check if pension topic fits their innovation support | F6: Innovation support, partner finding, scaling | G6: Relevant if they see us as an innovation/startup project with partner-finding and market-launch potential | H6: Reach startup ecosystem, innovation partners, and scaling-support structures through their startup and partner-finding support | I6: We are building a retirement-rights solution for internationally mobile professionals and employers | J6: Innovation support / partner finding / scaling support | K6: Mission-based support for innovation projects | L6: Partner finding, startup support, market-launch preparation, funding orientation | M6: Innovation case, ecosystem contribution, pilot | N6: Inna Perepelytsya — Senior Advisor — inna.perepelytsya@luxinnovation.lu Sven Baltes — Manager – Startup Relations — sven.baltes@luxinnovation.lu | O6: Whether they see the project as strong enough innovation fit
A7: Social Business Incubator (SBI) | B7: Hub / Public Body | C7: Medium | D7: Researching | E7: Contact SBI; propose social-impact angle on financial inclusion for mobile workers | F7: Social impact channel, inclusion angle | G7: If positioned as financial inclusion / long-term resilience for internationally mobile people, it fits their social-impact support logic | H7: Reach social entrepreneurs, impact projects, and communities where financial clarity is part of social inclusion | I7: We want to improve long-term financial clarity and pension access for internationally mobile people | J7: Impact partnership / workshop / ecosystem intro | K7: Likely mission-based support | L7: Advice, training, impact-network intros, social positioning | M7: Financial wellbeing / inclusion workshop, impact framing | N7: contact@sbi.lu | O7: Whether our project is impact-oriented enough for active support
A8: Luxembourg Employers' Association (UEL) | B8: Federation | C8: High | D8: Researching | E8: Research UEL employer events; identify contact for employer-facing pension content | F8: Employer credibility, policy visibility | G8: Our solution can support employers dealing with internationally mobile employees and long-term employee wellbeing topics | H8: Reach employers, business leaders, and employer associations; strong B2B credibility and policy-level visibility | I8: We help employers support internationally mobile employees facing fragmented pension rights across countries | J8: Employer pilot / policy discussion / event / content | K8: Likely institutional and selective; contact possible through public route | L8: Employer credibility, possible introductions, policy/business visibility | M8: Employer-benefit angle, educational content, pilot idea | N8: Jean-Paul Olinger / public route press@uel.lu | O8: Best operational contact and whether topic fits their agenda
A9: ALFI – Association of the Luxembourg Fund Industry | B9: Federation | C9: Medium-High | D9: Researching | E9: Check ALFI event calendar; propose educational session on pension rights for fund professionals | F9: Finance network, premium visibility | G9: Relevant if positioned around international finance professionals, mobility, and long-term retirement/wealth-planning literacy | H9: Reach international finance professionals, member firms, and industry visibility in Luxembourg finance ecosystem | I9: We help employers support internationally mobile employees facing fragmented pension rights across countries | J9: Thought leadership / event / finance-community content | K9: Likely member-driven and industry-focused | L9: Events, premium visibility, finance-network access | M9: Educational session, finance-focused guide, premium pilot audience | O9: Whether they would see this as relevant beyond investment/fund topics
A10: Luxembourg for Finance (LFF) | B10: Hub / Public Body | C10: Medium-High | D10: Researching | E10: Contact LFF team; explore thought-leadership content on pension portability for finance sector | F10: Finance ecosystem visibility, intros | G10: Strong fit for the international-finance and international-talent angle; your topic is relevant for globally mobile finance professionals | H10: Reach international finance audience, institutions, and financial-ecosystem visibility | I10: We help employers support internationally mobile employees facing fragmented pension rights across countries | J10: Event / ecosystem intro / thought leadership / visibility | K10: Likely institutional and fit-driven | L10: Visibility, finance-community access, ecosystem introductions | M10: Finance-professional guide, panel topic, educational session | N10: Jonathan Westhead — Head of Communications — jonathan.westhead@lff.lu | O10: Whether they would host or circulate a topic like this
A11: FEDIL – The Voice of Luxembourg’s Industry | B11: Federation | C11: Medium-High | D11: Researching | E11: Research FEDIL member events; identify HR/employer-services contact | F11: Industrial employer reach, B2B channel | G11: Relevant for employers with international talent and cross-border workforce management needs | H11: Reach industrial employers, HR/business leaders, and employer network visibility | I11: We help employers support internationally mobile employees facing fragmented pension rights across countries | J11: Employer pilot / event / content / referrals | K11: Likely association-based and agenda-driven | L11: Employer network, business visibility, sector reach | M11: Employer-facing workshop, international-workforce support angle | O11: Best contact person and whether topic fits employer agenda
A12: APSI Luxembourg | B12: Federation | C12: Medium | D12: Researching | E12: Check APSI events; explore digital-pension-tools angle for tech community | F12: Tech community, digital ecosystem | G12: Relevant if positioned as digital infrastructure / fintech / regtech / employee-digital-services topic | H12: Reach Luxembourg tech community, digital leaders, and ecosystem visibility | I12: We help employers support internationally mobile employees facing fragmented pension rights across countries | J12: Ecosystem intro / event / visibility / tech-community content | K12: Likely association/community-based | L12: Tech visibility, digital ecosystem access, possible event channel | M12: Digital-use-case angle, startup/fintech story, product demo | O12: Whether they are a strong enough GTM route versus only visibility
A13: LPEA – Luxembourg Private Equity & Venture Capital Association | B13: Federation | C13: Medium-High | D13: Researching | E13: Research LPEA events calendar; propose PE/VC-angle session on founder pension complexity | F13: PE/VC network, premium finance access | G13: Our solution is relevant to an international finance audience with highly mobile careers; LPEA's mission is to connect, inform, and represent the PE/VC ecosystem. | H13: Reach PE/VC firms, private banks, family offices, advisors, and highly international professionals; gain premium finance visibility and potential employer-level access. | I13: We help internationally mobile professionals and employers in finance understand and organize fragmented pension rights across countries. | J13: Event / thought leadership / employer pilot / finance-community content | K13: Clear membership-based association, but direct contact is open. | L13: Events, network access, industry visibility, premium-segment credibility, knowledge-sharing platform. | M13: Finance-focused educational session, premium professional guide, pilot group, thought leadership content. | N13: Claus Mansfeldt — President — claus.mansfeldt@lpea.lu Stephane Pesch — CEO — stephane.pesch@lpea.lu Johann Herz — Head of Events & Communication — johann.herz@lpea.lu | O13: Whether non-members can speak, publish, or co-host; best operational contact beyond general office.
A14: LBAN – Luxembourg Business Angel Network | B14: Hub / Public Body | C14: Medium | D14: Researching | E14: Contact LBAN network manager; explore startup-founder pension workshop | F14: Angel/founder network, startup intros | G14: Relevant if we position the solution for founders, investors, and internationally mobile startup operators; LBAN's mission is to connect business angels with the entrepreneurial ecosystem and support startup growth. | H14: Reach angel investors, founders, startup teams, and ecosystem actors; gain startup/investor visibility and possible intros to founder communities and early adopters. | I14: We help internationally mobile professionals and employers in finance understand and organize fragmented pension rights across countries. | J14: Event / startup-investor content / ecosystem intro / pilot | K14: Membership/network-based, but general contact is open. | L14: Investor/startup ecosystem visibility, founder access, event/network route, community credibility. | M14: Founder/investor education session, startup-team guide, pilot-user angle, ecosystem content. | N14: info@lban.lu; public contacts include Michel Rzonzef (President) and Teona Khubutia (Manager). | O14: Whether they see the topic as relevant enough for members; whether event/content collaboration requires membership or sponsor route.
A15: Maison Moderne / Paperjam / Delano | B15: Media | C15: High | D15: Researching | E15: Research Paperjam/Delano editorial calendar; propose thought-leadership article or interview | F15: Visibility, thought leadership, audience | G15: Strong editorial relevance if framed as international talent, retirement fragmentation, and employer/expat financial clarity in Luxembourg | H15: Reach business audience, employers, decision-makers, and broad Luxembourg visibility through media exposure | I15: We are building a retirement-rights solution for internationally mobile professionals and employers | J15: Media / thought leadership / interview / article | K15: Editorial fit required; not a classic partnership | L15: Visibility, credibility, audience reach, story amplification | M15: Article angle, expert commentary, ecosystem story | N15: Aaron Grunwald — Editor-in-chief at Delano — aaron.grunwald@maisonmoderne.com Thierry Labro — Editor-in-chief at Delano — thierry.labro@maisonmoderne.com | O15: Best story angle: expat, talent, pensions, founder journey, or fintech
A16: ABBL – Luxembourg Bankers' Association | B16: Federation | C16: High | D16: Researching | E16: Research contact route; check if ABBL has HR / mobility working group | F16: Banking employer reach, finance-professional access, premium visibility | G16: Largest financial-sector association; many member banks employ highly mobile international professionals whose pension rights fragment across countries | H16: Reach banks, financial intermediaries, and their internationally mobile employees; gain premium financial-sector credibility and employer-level access | I16: We help employers and internationally mobile professionals in finance understand and organize fragmented pension rights across countries | J16: Employer pilot / event / thought leadership / finance-community content | K16: Member-driven association; first contact open via public route | L16: Events, employer network, finance-sector visibility, working-group access, premium credibility | M16: Finance-professional pension guide, employer-facing educational session, pilot audience, thought leadership content | O16: Best operational contact; whether topic fits their employer/HR agenda or innovation working group
A17: HRCommunity.lu | B17: HR Network | C17: High | D17: Researching | E17: Contact via website; propose educational session on cross-border pension rights for HR professionals | F17: Direct HR decision-maker access, employer-benefit channel, event route | G17: Reference HR community in Luxembourg since 1992; their member companies manage internationally mobile employees whose pension rights are a real HR pain point | H17: Direct access to HR directors and people managers across all sectors; visibility as an expert solution for cross-border employee benefits | I17: We help HR professionals support internationally mobile employees facing fragmented pension rights across countries | J17: Event / workshop / content / employer pilot | K17: Membership-based community of HR professionals; contact open through website | L17: HR-community events, employer network, sector-wide HR visibility, knowledge-sharing platform | M17: Cross-border pension workshop for HR teams, practical employer guide, pilot group, thought leadership | O17: Whether they host external expert sessions; best contact for partnership discussions
A18: ADEM – Agence pour le Développement de l'Emploi | B18: Hub / Public Body | C18: High | D18: Researching | E18: Research public contact route; explore if they have expat integration or employer-services team | F18: Expat integration channel, employer services, public-sector credibility | G18: Luxembourg's public employment agency; directly assists cross-border workers and expats with professional integration — pension and social security clarity is a natural extension | H18: Reach internationally mobile jobseekers and employers through ADEM's integration services; public-sector credibility and visibility | I18: We help internationally mobile professionals and employers understand and organize fragmented pension rights across countries | J18: Information partnership / content / referral / workshop | K18: Public institution; contact open through official channels | L18: Expat integration reach, employer services access, public-sector referral channel, credibility | M18: Pension-rights information resource for expats, employer guide, educational content for integration services | O18: Whether they have an employer-services or expat-integration team; best contact route for partnerships
A19: Luxembourg-City Incubator (LCI) | B19: Hub / Public Body | C19: Medium-High | D19: Researching | E19: Contact via HoST or directly; check if incubated startups fit as pilot audience | F19: International founder access, startup pilot users, ecosystem intro | G19: City-backed incubator for early-stage companies; many incubated founders are internationally mobile and face cross-border pension complexity | H19: Access to international startup founders as pilot users; visibility in the incubator ecosystem; complementary channel to HoST | I19: We help founders and startup talent with international careers get clarity on fragmented pension rights | J19: Workshop / pilot / ecosystem intro | K19: Backed by City of Luxembourg and Chamber of Commerce; likely mission-based, open to collaboration | L19: Startup-founder access, event channel, incubator community, pilot audience | M19: Founder pension workshop, practical guide, pilot session for incubated startups | O19: Whether collaboration needs to go through HoST or can be direct; best contact for event/workshop proposals
A20: Technoport | B20: Hub / Public Body | C20: Medium-High | D20: Researching | E20: Contact via website; check if they run community events for resident startups | F20: International startup access, tech-founder community, ecosystem intro | G20: National technology incubator; often the first local hub for international startups arriving in Luxembourg — these founders face immediate cross-border pension fragmentation | H20: Reach international tech founders at the moment they relocate to Luxembourg; pilot-user access and ecosystem credibility | I20: We help founders and startup talent with international careers get clarity on fragmented pension rights | J20: Workshop / pilot / ecosystem intro / content | K20: Public incubator; likely mission-based and open to collaboration | L20: International-founder community, event channel, ecosystem credibility, early-stage access | M20: Founder pension workshop, relocation guide for international startups, pilot session | O20: Whether they run community programming; best contact for workshop/content proposals
A21: CFA Society Luxembourg | B21: Federation | C21: High | D21: Researching | E21: Check CFA Society events calendar; propose educational session on pension portability for CFA members | F21: Finance-professional network, premium credibility, educational events | G21: Professional society for CFA charterholders and candidates since 2003; members are highly international finance professionals — exactly the profile with fragmented pension rights across multiple countries | H21: Direct access to internationally mobile investment professionals; high pension-relevance; monthly educational conferences and networking events with 20-200 attendees | I21: We help internationally mobile finance professionals understand and organize pension rights scattered across the countries where they've built their careers | J21: Event / educational session / thought leadership / professional development content | K21: Membership open to CFA Institute members and candidates; events generally open to members; speaker proposals likely welcome | L21: Monthly conferences, networking events, newsletter, premium finance-professional audience, educational platform | M21: Pension-portability educational session for CFA members, practical guide for internationally mobile finance professionals, thought leadership content | O21: Whether they host external speaker sessions; best contact for educational content proposals
A22: ACA – Association des Compagnies d'Assurances | B22: Federation | C22: High | D22: Researching | E22: Contact ACA; explore pension/insurance pillar 2-3 content collaboration | F22: Insurance industry access, pension-pillar expertise, policy credibility | G22: Professional association of 146 Luxembourg insurers and reinsurers; directly involved in government consultations on Luxembourg's public pension system and second/third pillar reform | H22: Access to the insurance industry that designs and distributes pension products; partnership credibility on pension topics; visibility in policy discussions | I22: We complement pillar 2-3 pension products by helping internationally mobile workers understand their fragmented pillar 1 rights across countries | J22: Content partnership / thought leadership / event / policy input | K22: Member-driven industry association; contact via ACA management | L22: Insurance industry network, pension policy access, events, working groups, House of Finance co-location with ABBL/ALFI/LFF | M22: Cross-border pension insight for insurance members, educational content for employers using pillar 2-3 products, thought leadership | O22: Whether pension/employee-benefits working group exists; best contact for content partnership
A23: ILA – Institut Luxembourgeois des Administrateurs | B23: Federation | C23: High | D23: Researching | E23: Check ILA events calendar; propose governance-angle session on pension portability for board directors | F23: Senior executive access, governance community, board-level credibility | G23: Luxembourg's leading institute for corporate directors and governance professionals since 2005; 3,500+ members including board directors of international companies with careers spanning multiple countries | H23: Access to 3,500+ senior governance professionals — exactly the profile with fragmented pension rights from multi-country board careers; training/certification events | I23: Board directors with international careers have pension rights scattered across multiple countries. We help them track and organize those rights. | J23: Training session / governance event / thought leadership / member benefit | K23: Membership-based; offers training, certification, and networking; open to speaker proposals | L23: 3,500+ member network, training events, governance certifications, newsletter, ecoDa European network | M23: Pension-portability session for board directors, practical guide for governance professionals, thought leadership | O23: Whether they host external expert sessions in their training program; best contact for partnership
A24: ILAC – Institut Luxembourgeois des Actuaires | B24: Federation | C24: Medium-High | D24: Researching | E24: Contact ILAC bureau; propose actuarial-angle session on cross-border pension portability | F24: Pension-specialist community, technical credibility, insurance-sector access | G24: Institute of ~300 actuaries active in Luxembourg since 1992; actuaries are pension specialists by profession — they design and value the pension products that internationally mobile workers accumulate across countries | H24: Access to 300 pension/insurance specialists; natural amplifiers who understand the technical complexity; conferences attract 150+ professionals | I24: Actuaries understand cross-border pension complexity better than anyone. We give their clients the tools to navigate it. | J24: Conference session / technical partnership / CPD content | K24: Professional institute; regular open conferences; CPD program for members | L24: Actuarial conferences, CPD program, technical community, Actuview platform partnership | M24: Cross-border pension data/insight session for actuaries, CPD-eligible content, technical partnership | O24: Whether CPD session proposals are open; best contact at ILAC bureau
A25: AMMD – Association des Médecins et Médecins-Dentistes | B25: Federation | C25: Medium | D25: Researching | E25: Contact AMMD secretariat; explore whether pension/financial-planning content fits their member services | F25: Medical professional access, healthcare-sector credibility, CNS/social security link | G25: Luxembourg's most representative medical association since 1904; key liaison between the medical profession, the Ministry of Health, and the CNS (national health fund). Doctors in LU are highly international — many trained abroad with pension rights in other countries. | H25: Access to ~800-900 doctors and dentists, many of whom trained and worked abroad before settling in LU; direct link to CNS and social security system | I25: Doctors who trained and worked in other countries before practicing in Luxembourg have pension rights scattered across multiple systems. We help them track and organize those rights. | J25: Member information service / event / content partnership | K25: Membership requires practicing authorization in LU; union-like structure; contact via secretariat | L25: Medical professional network, member communications, Scientific Council, link to CNS/Ministry of Health | M25: Pension-rights information resource for international doctors, practical guide for medical professionals relocating to/from LU | O25: Whether they provide member services beyond union representation; best contact for information partnership
A26: INGSCI – Ingénieurs et Scientifiques du Luxembourg | B26: Federation | C26: Medium | D26: Researching | E26: Contact INGSCI via secretariat; explore whether pension topic fits their Journée de l'Ingénieur or conference program | F26: Engineering professional access, cross-border network (Saar-Lor-Lux), industry events | G26: Luxembourg's voluntary association for engineers, architects, scientists and industrials; hosts the annual Journée de l'Ingénieur, conferences, and cross-border Saar-Lor-Lux events with engineering associations in Germany and France. Many members trained abroad. | H26: Access to internationally trained engineers with careers spanning multiple countries; cross-border cooperation with DE/FR engineering associations directly touches pension fragmentation zone | I26: Engineers who trained and worked in multiple countries before settling in Luxembourg have pension rights scattered across those systems. We help them organize and understand those rights. | J26: Conference session / Journée de l'Ingénieur / cross-border event / content | K26: Voluntary membership; hosts events at Forum da Vinci; open to speaker proposals | L26: Annual Journée de l'Ingénieur, conferences, cross-border Saar-Lor-Lux network, Forum da Vinci venue, publications | M26: Cross-border pension workshop for engineers, practical guide for mobile professionals, Saar-Lor-Lux themed session | O26: Whether Journée de l'Ingénieur accepts external speakers; best contact at secretariat
A27: Barreau de Luxembourg (Bar Association) | B27: Federation | C27: Medium-High | D27: Researching | E27: Research Barreau CPD program; check if pension/social-security topic qualifies for CLE points | F27: Legal professional access, CPD channel, cross-border expertise community | G27: Luxembourg Bar Association with 3,250 members; very international — EU lawyers can register under home-country title. Major international law firms (A&O, Clifford Chance, etc.) have LU offices. Lawyers require 16 CPD points/year. Many cross-border practitioners. | H27: Access to 3,250 legal professionals, many internationally mobile; CPD requirement creates event attendance; cross-border lawyers face pension fragmentation between home country and LU | I27: Lawyers with international careers across multiple jurisdictions have pension rights scattered in each country they've practiced. We help them track and organize those rights. | J27: CPD session / conference / member information | K27: Statutory professional body; mandatory membership; runs CPD program; more regulatory than networking-focused | L27: 3,250-member reach, CPD training program, professional directory, disciplinary authority | M27: CPD-eligible session on cross-border pension rights for legal practitioners, practical guide for international lawyers in LU | O27: Whether pension/financial topic qualifies for CPD points; whether external speakers can propose sessions; contact at Bar Council
A28: OEC – Ordre des Experts-Comptables | B28: Federation | C28: Medium-High | D28: Researching | E28: Contact OEC; explore whether cross-border pension/tax topic fits their CPD program (60 credits/3 years) | F28: Accountancy professional access, CPD channel, fund-industry link, tax/pension expertise community | G28: Professional order for 1,168 chartered accountants and 553 firms in Luxembourg; mandatory membership. Many serve the fund industry (€3.5T+ AUM) and international corporate structures. EU-qualified accountants can practice in LU under mutual recognition — highly international workforce. | H28: Access to 1,168 accountants who advise international clients on tax/financial structures; CPD requirement (60 credits/3 years) creates captive training audience; direct link to fund industry | I28: Chartered accountants advise internationally mobile clients and employers on tax and financial planning. Cross-border pension rights are a natural extension of that advice. | J28: CPD session / training content / professional development | K28: Mandatory professional order; CPD program with training partnerships; co-located at 14 rue Erasme | L28: 1,168-member reach, CPD training program, peer review system, Accountancy Europe membership, fund industry connection | M28: CPD-eligible session on cross-border pension rights for accountants, practical guide for advising internationally mobile clients, tax-pension integration content | O28: Whether external CPD content proposals are accepted; contact at OEC secretariat

Sheet Ring 2 — Communities
A1: Organization | B1: Country Link | C1: Category | D1: Priority | E1: Status | F1: Next Action | G1: GTM Role | H1: Why They Care | I1: Our Interest | J1: Main Message | K1: Partnership Type | L1: Access Conditions | M1: Support They Can Offer | N1: What We Offer | O1: Contact Person | P1: Need to Confirm
A2: AMCHAM Luxembourg | B2: US / EN-speaking | C2: Country Community | D2: High | E2: Researching | F2: Check AMCHAM events calendar; explore committee membership or speaker opportunity | G2: Employer reach, expat events, committees | H2: We offer relevant member value for international companies and international employees; fits their information/problem-solving role | I2: Reach English-speaking employers, expat professionals, HR contacts, and member companies through events and committees | J2: We help international professionals and employers navigate fragmented pension rights built across Europe | K2: Event / employer pilot / content / committee discussion | L2: Likely member-driven; collaboration may depend on format or sponsorship | M2: Member events, employer visibility, committee access, newsletters | N2: Educational session, employer-benefit angle, guide, sharing news on changes in pension rights. | O2: Daniel McKenzie — Head of Communications, Events and Committee Structures — daniel@amcham.lu | P2: Whether speaking or content visibility needs membership or sponsor status or can start as external expert contribution
